2018-03-26 09:16:16,006 ERROR: Exception on /auth/login [POST] [in /Users/cdcf/t-e-manager/venv/lib/python3.6/site-packages/flask/app.py:1560]
Traceback (most recent call last):
  File "/Users/cdcf/t-e-manager/venv/lib/python3.6/site-packages/flask/app.py", line 1982, in wsgi_app
    response = self.full_dispatch_request()
  File "/Users/cdcf/t-e-manager/venv/lib/python3.6/site-packages/flask/app.py", line 1614, in full_dispatch_request
    rv = self.handle_user_exception(e)
  File "/Users/cdcf/t-e-manager/venv/lib/python3.6/site-packages/flask/app.py", line 1517, in handle_user_exception
    reraise(exc_type, exc_value, tb)
  File "/Users/cdcf/t-e-manager/venv/lib/python3.6/site-packages/flask/_compat.py", line 33, in reraise
    raise value
  File "/Users/cdcf/t-e-manager/venv/lib/python3.6/site-packages/flask/app.py", line 1612, in full_dispatch_request
    rv = self.dispatch_request()
  File "/Users/cdcf/t-e-manager/venv/lib/python3.6/site-packages/flask/app.py", line 1598, in dispatch_request
    return self.view_functions[rule.endpoint](**req.view_args)
  File "/Users/cdcf/t-e-manager/app/auth/routes.py", line 20, in login
    user = User.query.filter_by(username=form.username.data).first()
  File "/Users/cdcf/t-e-manager/venv/lib/python3.6/site-packages/flask_sqlalchemy/__init__.py", line 512, in __get__
    mapper = orm.class_mapper(type)
  File "/Users/cdcf/t-e-manager/venv/lib/python3.6/site-packages/sqlalchemy/orm/base.py", line 421, in class_mapper
    mapper = _inspect_mapped_class(class_, configure=configure)
  File "/Users/cdcf/t-e-manager/venv/lib/python3.6/site-packages/sqlalchemy/orm/base.py", line 400, in _inspect_mapped_class
    mapper._configure_all()
  File "/Users/cdcf/t-e-manager/venv/lib/python3.6/site-packages/sqlalchemy/orm/mapper.py", line 1223, in _configure_all
    configure_mappers()
  File "/Users/cdcf/t-e-manager/venv/lib/python3.6/site-packages/sqlalchemy/orm/mapper.py", line 2873, in configure_mappers
    mapper._post_configure_properties()
  File "/Users/cdcf/t-e-manager/venv/lib/python3.6/site-packages/sqlalchemy/orm/mapper.py", line 1766, in _post_configure_properties
    prop.init()
  File "/Users/cdcf/t-e-manager/venv/lib/python3.6/site-packages/sqlalchemy/orm/interfaces.py", line 184, in init
    self.do_init()
  File "/Users/cdcf/t-e-manager/venv/lib/python3.6/site-packages/sqlalchemy/orm/relationships.py", line 1653, in do_init
    self._process_dependent_arguments()
  File "/Users/cdcf/t-e-manager/venv/lib/python3.6/site-packages/sqlalchemy/orm/relationships.py", line 1710, in _process_dependent_arguments
    self.target = self.mapper.mapped_table
  File "/Users/cdcf/t-e-manager/venv/lib/python3.6/site-packages/sqlalchemy/util/langhelpers.py", line 767, in __get__
    obj.__dict__[self.__name__] = result = self.fget(obj)
  File "/Users/cdcf/t-e-manager/venv/lib/python3.6/site-packages/sqlalchemy/orm/relationships.py", line 1626, in mapper
    argument = self.argument()
  File "/Users/cdcf/t-e-manager/venv/lib/python3.6/site-packages/sqlalchemy/ext/declarative/clsregistry.py", line 281, in __call__
    x = eval(self.arg, globals(), self._dict)
  File "<string>", line 1
    Category Type
                ^
SyntaxError: unexpected EOF while parsing
2018-03-26 09:18:01,170 INFO: t-e-manager startup [in /Users/cdcf/t-e-manager/app/__init__.py:92]
2018-03-26 09:18:28,928 INFO: t-e-manager startup [in /Users/cdcf/t-e-manager/app/__init__.py:92]
2018-03-26 09:18:35,499 ERROR: Exception on /auth/login [POST] [in /Users/cdcf/t-e-manager/venv/lib/python3.6/site-packages/flask/app.py:1560]
Traceback (most recent call last):
  File "/Users/cdcf/t-e-manager/venv/lib/python3.6/site-packages/flask/app.py", line 1982, in wsgi_app
    response = self.full_dispatch_request()
  File "/Users/cdcf/t-e-manager/venv/lib/python3.6/site-packages/flask/app.py", line 1614, in full_dispatch_request
    rv = self.handle_user_exception(e)
  File "/Users/cdcf/t-e-manager/venv/lib/python3.6/site-packages/flask/app.py", line 1517, in handle_user_exception
    reraise(exc_type, exc_value, tb)
  File "/Users/cdcf/t-e-manager/venv/lib/python3.6/site-packages/flask/_compat.py", line 33, in reraise
    raise value
  File "/Users/cdcf/t-e-manager/venv/lib/python3.6/site-packages/flask/app.py", line 1612, in full_dispatch_request
    rv = self.dispatch_request()
  File "/Users/cdcf/t-e-manager/venv/lib/python3.6/site-packages/flask/app.py", line 1598, in dispatch_request
    return self.view_functions[rule.endpoint](**req.view_args)
  File "/Users/cdcf/t-e-manager/app/auth/routes.py", line 20, in login
    user = User.query.filter_by(username=form.username.data).first()
  File "/Users/cdcf/t-e-manager/venv/lib/python3.6/site-packages/flask_sqlalchemy/__init__.py", line 512, in __get__
    mapper = orm.class_mapper(type)
  File "/Users/cdcf/t-e-manager/venv/lib/python3.6/site-packages/sqlalchemy/orm/base.py", line 421, in class_mapper
    mapper = _inspect_mapped_class(class_, configure=configure)
  File "/Users/cdcf/t-e-manager/venv/lib/python3.6/site-packages/sqlalchemy/orm/base.py", line 400, in _inspect_mapped_class
    mapper._configure_all()
  File "/Users/cdcf/t-e-manager/venv/lib/python3.6/site-packages/sqlalchemy/orm/mapper.py", line 1223, in _configure_all
    configure_mappers()
  File "/Users/cdcf/t-e-manager/venv/lib/python3.6/site-packages/sqlalchemy/orm/mapper.py", line 2873, in configure_mappers
    mapper._post_configure_properties()
  File "/Users/cdcf/t-e-manager/venv/lib/python3.6/site-packages/sqlalchemy/orm/mapper.py", line 1766, in _post_configure_properties
    prop.init()
  File "/Users/cdcf/t-e-manager/venv/lib/python3.6/site-packages/sqlalchemy/orm/interfaces.py", line 184, in init
    self.do_init()
  File "/Users/cdcf/t-e-manager/venv/lib/python3.6/site-packages/sqlalchemy/orm/relationships.py", line 1653, in do_init
    self._process_dependent_arguments()
  File "/Users/cdcf/t-e-manager/venv/lib/python3.6/site-packages/sqlalchemy/orm/relationships.py", line 1710, in _process_dependent_arguments
    self.target = self.mapper.mapped_table
  File "/Users/cdcf/t-e-manager/venv/lib/python3.6/site-packages/sqlalchemy/util/langhelpers.py", line 767, in __get__
    obj.__dict__[self.__name__] = result = self.fget(obj)
  File "/Users/cdcf/t-e-manager/venv/lib/python3.6/site-packages/sqlalchemy/orm/relationships.py", line 1626, in mapper
    argument = self.argument()
  File "/Users/cdcf/t-e-manager/venv/lib/python3.6/site-packages/sqlalchemy/ext/declarative/clsregistry.py", line 281, in __call__
    x = eval(self.arg, globals(), self._dict)
  File "<string>", line 1
    Category Type
                ^
SyntaxError: unexpected EOF while parsing
2018-03-26 09:20:59,673 INFO: t-e-manager startup [in /Users/cdcf/t-e-manager/app/__init__.py:92]
2018-03-26 09:21:33,728 ERROR: Exception on /auth/login [POST] [in /Users/cdcf/t-e-manager/venv/lib/python3.6/site-packages/flask/app.py:1560]
Traceback (most recent call last):
  File "/Users/cdcf/t-e-manager/venv/lib/python3.6/site-packages/flask/app.py", line 1982, in wsgi_app
    response = self.full_dispatch_request()
  File "/Users/cdcf/t-e-manager/venv/lib/python3.6/site-packages/flask/app.py", line 1614, in full_dispatch_request
    rv = self.handle_user_exception(e)
  File "/Users/cdcf/t-e-manager/venv/lib/python3.6/site-packages/flask/app.py", line 1517, in handle_user_exception
    reraise(exc_type, exc_value, tb)
  File "/Users/cdcf/t-e-manager/venv/lib/python3.6/site-packages/flask/_compat.py", line 33, in reraise
    raise value
  File "/Users/cdcf/t-e-manager/venv/lib/python3.6/site-packages/flask/app.py", line 1612, in full_dispatch_request
    rv = self.dispatch_request()
  File "/Users/cdcf/t-e-manager/venv/lib/python3.6/site-packages/flask/app.py", line 1598, in dispatch_request
    return self.view_functions[rule.endpoint](**req.view_args)
  File "/Users/cdcf/t-e-manager/app/auth/routes.py", line 20, in login
    user = User.query.filter_by(username=form.username.data).first()
  File "/Users/cdcf/t-e-manager/venv/lib/python3.6/site-packages/flask_sqlalchemy/__init__.py", line 512, in __get__
    mapper = orm.class_mapper(type)
  File "/Users/cdcf/t-e-manager/venv/lib/python3.6/site-packages/sqlalchemy/orm/base.py", line 421, in class_mapper
    mapper = _inspect_mapped_class(class_, configure=configure)
  File "/Users/cdcf/t-e-manager/venv/lib/python3.6/site-packages/sqlalchemy/orm/base.py", line 400, in _inspect_mapped_class
    mapper._configure_all()
  File "/Users/cdcf/t-e-manager/venv/lib/python3.6/site-packages/sqlalchemy/orm/mapper.py", line 1223, in _configure_all
    configure_mappers()
  File "/Users/cdcf/t-e-manager/venv/lib/python3.6/site-packages/sqlalchemy/orm/mapper.py", line 2873, in configure_mappers
    mapper._post_configure_properties()
  File "/Users/cdcf/t-e-manager/venv/lib/python3.6/site-packages/sqlalchemy/orm/mapper.py", line 1766, in _post_configure_properties
    prop.init()
  File "/Users/cdcf/t-e-manager/venv/lib/python3.6/site-packages/sqlalchemy/orm/interfaces.py", line 184, in init
    self.do_init()
  File "/Users/cdcf/t-e-manager/venv/lib/python3.6/site-packages/sqlalchemy/orm/relationships.py", line 1653, in do_init
    self._process_dependent_arguments()
  File "/Users/cdcf/t-e-manager/venv/lib/python3.6/site-packages/sqlalchemy/orm/relationships.py", line 1710, in _process_dependent_arguments
    self.target = self.mapper.mapped_table
  File "/Users/cdcf/t-e-manager/venv/lib/python3.6/site-packages/sqlalchemy/util/langhelpers.py", line 767, in __get__
    obj.__dict__[self.__name__] = result = self.fget(obj)
  File "/Users/cdcf/t-e-manager/venv/lib/python3.6/site-packages/sqlalchemy/orm/relationships.py", line 1626, in mapper
    argument = self.argument()
  File "/Users/cdcf/t-e-manager/venv/lib/python3.6/site-packages/sqlalchemy/ext/declarative/clsregistry.py", line 281, in __call__
    x = eval(self.arg, globals(), self._dict)
  File "<string>", line 1
    Category Type
                ^
SyntaxError: unexpected EOF while parsing
2018-03-26 15:39:36,009 INFO: t-e-manager startup [in /Users/cdcf/t-e-manager/app/__init__.py:83]
2018-03-26 15:39:51,256 INFO: t-e-manager startup [in /Users/cdcf/t-e-manager/app/__init__.py:83]
